{"_default": {"1": {"waltervargas": {"issues": [{"url": "https://api.github.com/repos/waltervargas/prestashoperpconnect/issues/9", "title": "error on sync order lines.", "body": "``` python\n2014-09-12 05:55:57,223 8183 ERROR salling5 openerp.addons.connector.queue.worker: Traceback (most recent call last):\n  File \"/opt/openerp/addons-connector/connector/queue/worker.py\", line 122, in run_job\n    job.perform(session)\n  File \"/opt/openerp/addons-connector/connector/queue/job.py\", line 490, in perform\n    self.result = self.func(session, *self.args, **self.kwargs)\n  File \"/opt/openerp/addons-connector/prestashoperpconnect/unit/import_synchronizer.py\", line 1036, in import_record\n    importer.run(prestashop_id)\n  File \"/opt/openerp/addons-connector/prestashoperpconnect/unit/import_synchronizer.py\", line 149, in run\n    erp_id = self._create(record)\n  File \"/opt/openerp/addons-connector/prestashoperpconnect/unit/import_synchronizer.py\", line 92, in _create\n    vals = data.values()\n  File \"/opt/openerp/addons-connector/connector/unit/mapper.py\", line 902, in values\n    values = self._mapper._apply(self, options=options)\n  File \"/opt/openerp/addons-connector/connector/unit/mapper.py\", line 641, in _apply\n    return self._apply_with_options(map_record)\n  File \"/opt/openerp/addons-connector/connector/unit/mapper.py\", line 691, in _apply_with_options\n    to_attr, model_name)\n  File \"/opt/openerp/addons-connector/prestashoperpconnect/unit/mapper.py\", line 403, in _map_child\n    child_records = from_attr(self, record)\n  File \"/opt/openerp/addons-connector/prestashoperpconnect/unit/mapper.py\", line 387, in _get_sale_order_lines\n    orders = record['associations'].get('order_rows', {}).get('order_row', [])\nTypeError: 'MapRecord' object has no attribute '__getitem__'\n```\n", "reactions": {"url": "https://api.github.com/repos/waltervargas/prestashoperpconnect/issues/9/reactions", "total_count": 0, "+1": 0, "-1": 0, "laugh": 0, "hooray": 0, "confused": 0, "heart": 0}, "author_association": "OWNER"}, {"url": "https://api.github.com/repos/waltervargas/prestashoperpconnect/issues/8", "title": "duplicate key value error on import products", "body": "``` python\n  File \"/home/vagrant/addons/connector/queue/worker.py\", line 122, in run_job\n    job.perform(session)\n  File \"/home/vagrant/addons/connector/queue/job.py\", line 490, in perform\n    self.result = self.func(session, *self.args, **self.kwargs)\n  File \"/home/vagrant/addons/prestashoperpconnect/unit/import_synchronizer.py\", line 1030, in import_record\n    importer.run(prestashop_id)\n  File \"/home/vagrant/addons/prestashoperpconnect/unit/import_synchronizer.py\", line 680, in run\n    self._after_import(erp_id)\n  File \"/home/vagrant/addons/prestashoperpconnect/unit/import_synchronizer.py\", line 768, in _after_import\n    self.import_combinations()\n  File \"/home/vagrant/addons/prestashoperpconnect/unit/import_synchronizer.py\", line 799, in import_combinations\n    combination['id']\n  File \"/home/vagrant/addons/prestashoperpconnect/unit/import_synchronizer.py\", line 1030, in import_record\n    importer.run(prestashop_id)\n  File \"/home/vagrant/addons/prestashoperpconnect/unit/import_synchronizer.py\", line 143, in run\n    self._import_dependencies()\n  File \"/home/vagrant/addons/prestashoperpconnect/product_combination.py\", line 65, in _import_dependencies\n    'prestashop.product.combination.option',\n  File \"/home/vagrant/addons/prestashoperpconnect/unit/import_synchronizer.py\", line 173, in _check_dependency\n    ext_id\n  File \"/home/vagrant/addons/prestashoperpconnect/unit/import_synchronizer.py\", line 1030, in import_record\n    importer.run(prestashop_id)\n  File \"/home/vagrant/addons/prestashoperpconnect/product_combination.py\", line 342, in run\n    super(ProductCombinationOptionRecordImport, self).run(ext_id)\n  File \"/home/vagrant/addons/prestashoperpconnect/unit/import_synchronizer.py\", line 160, in run\n    erp_id = self._create(record)\n  File \"/home/vagrant/addons/prestashoperpconnect/unit/import_synchronizer.py\", line 102, in _create\n    context=context\n  File \"/home/vagrant/addons/connector/producer.py\", line 43, in create\n    record_id = create_original(self, cr, uid, vals, context=context)\n  File \"/usr/lib/pymodules/python2.7/openerp/osv/orm.py\", line 4444, in create\n    record_id = self.pool.get(table).create(cr, user, tocreate[table], context=parent_context)\n  File \"/home/vagrant/addons/base_custom_attributes/custom_attributes.py\", line 312, in create\n    return super(attribute_attribute, self).create(cr, uid, vals, context)\n  File \"/home/vagrant/addons/connector/producer.py\", line 43, in create\n    record_id = create_original(self, cr, uid, vals, context=context)\n  File \"/usr/lib/pymodules/python2.7/openerp/osv/orm.py\", line 4444, in create\n    record_id = self.pool.get(table).create(cr, user, tocreate[table], context=parent_context)\n  File \"/usr/lib/pymodules/python2.7/openerp/addons/base/ir/ir_model.py\", line 345, in create\n    res = super(ir_model_fields,self).create(cr, user, vals, context)\n  File \"/home/vagrant/addons/connector/producer.py\", line 43, in create\n    record_id = create_original(self, cr, uid, vals, context=context)\n  File \"/usr/lib/pymodules/python2.7/openerp/osv/orm.py\", line 4515, in create\n    cr.execute('insert into \"'+self._table+'\" (id'+upd0+\") values (\"+str(id_new)+upd1+')', tuple(upd2))\n  File \"/usr/lib/pymodules/python2.7/openerp/sql_db.py\", line 161, in wrapper\n    return f(self, *args, **kwargs)\n  File \"/usr/lib/pymodules/python2.7/openerp/sql_db.py\", line 226, in execute\n    res = self._obj.execute(query, params)\nIntegrityError: duplicate key value violates unique constraint \"ir_model_fields_name_model_uniq\"\nDETAIL:  Key (name, model_id)=(x_Color, 149) already exists.\n```\n", "reactions": {"url": "https://api.github.com/repos/waltervargas/prestashoperpconnect/issues/8/reactions", "total_count": 0, "+1": 0, "-1": 0, "laugh": 0, "hooray": 0, "confused": 0, "heart": 0}, "author_association": "OWNER"}, {"url": "https://api.github.com/repos/waltervargas/prestashoperpconnect/issues/7", "title": "Error on Import customer groups and customers ", "body": "``` python\n/usr/local/lib/python2.7/dist-packages/prestapyt-0.6.1-py2.7.egg/prestapyt/prestapyt.py:144: UserWarning: This library may not be compatible with this version of PrestaShop (1.6.0.8). Please upgrade/downgrade this library\n  \"Please upgrade/downgrade this library\") % (version,))\n2014-08-13 18:15:23,645 10554 ERROR salling5 openerp.addons.connector.queue.worker: Traceback (most recent call last):\n  File \"/home/vagrant/addons/connector/queue/worker.py\", line 122, in run_job\n    job.perform(session)\n  File \"/home/vagrant/addons/connector/queue/job.py\", line 490, in perform\n    self.result = self.func(session, *self.args, **self.kwargs)\n  File \"/home/vagrant/addons/prestashoperpconnect/unit/import_synchronizer.py\", line 1030, in import_record\n    importer.run(prestashop_id)\n  File \"/home/vagrant/addons/prestashoperpconnect/unit/import_synchronizer.py\", line 143, in run\n    self._import_dependencies()\n  File \"/home/vagrant/addons/prestashoperpconnect/unit/import_synchronizer.py\", line 321, in _import_dependencies\n    self.create_account(self.prestashop_record['id'], name)\nAttributeError: 'ResPartnerRecordImport' object has no attribute 'create_account'\n```\n", "reactions": {"url": "https://api.github.com/repos/waltervargas/prestashoperpconnect/issues/7/reactions", "total_count": 0, "+1": 0, "-1": 0, "laugh": 0, "hooray": 0, "confused": 0, "heart": 0}, "author_association": "OWNER"}], "commits": [], "pull_requests": [], "issue_comments": [{"url": "https://api.github.com/repos/waltervargas/prestashoperpconnect/issues/comments/49486248", "body": "fixed in the commit f57b7cfae698c5e846987c27217653032d8322ea\n", "reactions": {"url": "https://api.github.com/repos/waltervargas/prestashoperpconnect/issues/comments/49486248/reactions", "total_count": 0, "+1": 0, "-1": 0, "laugh": 0, "hooray": 0, "confused": 0, "heart": 0}, "author_association": "OWNER"}, {"url": "https://api.github.com/repos/waltervargas/prestashoperpconnect/issues/comments/49490952", "body": "## Problem for 'Synchronize Metadata'\n\nconnector: 2.2.0 (branch 7.0 from github)\nconnector_ecommerce: 2.1.0\nprestashoperpconnect: 0.3\n\n```\n2014-07-18 21:43:10,169 5947 ERROR salling3 openerp.osv.osv: Uncaught exception\nTraceback (most recent call last):\n  File \"/usr/lib/pymodules/python2.7/openerp/osv/osv.py\", line 132, in wrapper\n    return f(self, dbname, *args, **kwargs)\n  File \"/usr/lib/pymodules/python2.7/openerp/osv/osv.py\", line 199, in execute\n    res = self.execute_cr(cr, uid, obj, method, *args, **kw)\n  File \"/usr/lib/pymodules/python2.7/openerp/osv/osv.py\", line 187, in execute_cr\n    return getattr(object, method)(cr, uid, *args, **kw)\n  File \"/home/vagrant/addons/prestashoperpconnect/models/prestashop_model.py\", line 116, in synchronize_metadata\n    import_batch(session, model, backend_id)\n  File \"/home/vagrant/addons/prestashoperpconnect/unit/import_synchronizer.py\", line 1014, in import_batch\n    importer.run(filters=filters, **kwargs)\n  File \"/home/vagrant/addons/prestashoperpconnect/unit/import_synchronizer.py\", line 183, in run\n    record_ids = self._run_page(filters, **kwargs)\n  File \"/home/vagrant/addons/prestashoperpconnect/unit/import_synchronizer.py\", line 193, in _run_page\n    self._import_record(record_id, **kwargs)\n  File \"/home/vagrant/addons/prestashoperpconnect/unit/import_synchronizer.py\", line 259, in _import_record\n    record\n  File \"/home/vagrant/addons/prestashoperpconnect/unit/import_synchronizer.py\", line 1022, in import_record\n    importer.run(prestashop_id)\n  File \"/home/vagrant/addons/prestashoperpconnect/unit/import_synchronizer.py\", line 149, in run\n    erp_id = self._create(record)\n  File \"/home/vagrant/addons/prestashoperpconnect/unit/import_synchronizer.py\", line 98, in _create\n    context=context\n  File \"/home/vagrant/addons/connector/producer.py\", line 45, in create\n    record_id = create_original(self, cr, uid, vals, context=context)\n  File \"/usr/lib/pymodules/python2.7/openerp/osv/orm.py\", line 4394, in create\n    if vals.pop(f, None) is not None:\nAttributeError: 'MapRecord' object has no attribute 'pop'\n2014-07-18 21:43:10,179 5947 ERROR salling3 openerp.netsvc: 'MapRecord' object has no attribute 'pop'\nTraceback (most recent call last):\n  File \"/usr/lib/pymodules/python2.7/openerp/netsvc.py\", line 296, in dispatch_rpc\n    result = ExportService.getService(service_name).dispatch(method, params)\n  File \"/usr/lib/pymodules/python2.7/openerp/service/web_services.py\", line 626, in dispatch\n    res = fn(db, uid, *params)\n  File \"/usr/lib/pymodules/python2.7/openerp/osv/osv.py\", line 190, in execute_kw\n    return self.execute(db, uid, obj, method, *args, **kw or {})\n  File \"/usr/lib/pymodules/python2.7/openerp/osv/osv.py\", line 132, in wrapper\n    return f(self, dbname, *args, **kwargs)\n  File \"/usr/lib/pymodules/python2.7/openerp/osv/osv.py\", line 199, in execute\n    res = self.execute_cr(cr, uid, obj, method, *args, **kw)\n  File \"/usr/lib/pymodules/python2.7/openerp/osv/osv.py\", line 187, in execute_cr\n    return getattr(object, method)(cr, uid, *args, **kw)\n  File \"/home/vagrant/addons/prestashoperpconnect/models/prestashop_model.py\", line 116, in synchronize_metadata\n    import_batch(session, model, backend_id)\n  File \"/home/vagrant/addons/prestashoperpconnect/unit/import_synchronizer.py\", line 1014, in import_batch\n    importer.run(filters=filters, **kwargs)\n  File \"/home/vagrant/addons/prestashoperpconnect/unit/import_synchronizer.py\", line 183, in run\n    record_ids = self._run_page(filters, **kwargs)\n  File \"/home/vagrant/addons/prestashoperpconnect/unit/import_synchronizer.py\", line 193, in _run_page\n    self._import_record(record_id, **kwargs)\n  File \"/home/vagrant/addons/prestashoperpconnect/unit/import_synchronizer.py\", line 259, in _import_record\n    record\n  File \"/home/vagrant/addons/prestashoperpconnect/unit/import_synchronizer.py\", line 1022, in import_record\n    importer.run(prestashop_id)\n  File \"/home/vagrant/addons/prestashoperpconnect/unit/import_synchronizer.py\", line 149, in run\n    erp_id = self._create(record)\n  File \"/home/vagrant/addons/prestashoperpconnect/unit/import_synchronizer.py\", line 98, in _create\n    context=context\n  File \"/home/vagrant/addons/connector/producer.py\", line 45, in create\n    record_id = create_original(self, cr, uid, vals, context=context)\n  File \"/usr/lib/pymodules/python2.7/openerp/osv/orm.py\", line 4394, in create\n    if vals.pop(f, None) is not None:\nAttributeError: 'MapRecord' object has no attribute 'pop'\n```\n", "reactions": {"url": "https://api.github.com/repos/waltervargas/prestashoperpconnect/issues/comments/49490952/reactions", "total_count": 0, "+1": 0, "-1": 0, "laugh": 0, "hooray": 0, "confused": 0, "heart": 0}, "author_association": "OWNER"}, {"url": "https://api.github.com/repos/waltervargas/prestashoperpconnect/issues/comments/50133646", "body": "Gracias my friend, hoy pruebo.\n", "reactions": {"url": "https://api.github.com/repos/waltervargas/prestashoperpconnect/issues/comments/50133646/reactions", "total_count": 0, "+1": 0, "-1": 0, "laugh": 0, "hooray": 0, "confused": 0, "heart": 0}, "author_association": "OWNER"}, {"url": "https://api.github.com/repos/waltervargas/prestashoperpconnect/issues/comments/50225766", "body": "Not working my friend, the same error: \n\n```\n  File \"/home/vagrant/addons/prestashoperpconnect/unit/import_synchronizer.py\", line 149, in run\n    erp_id = self._create(record)\n  File \"/home/vagrant/addons/prestashoperpconnect/unit/import_synchronizer.py\", line 98, in _create\n    context=context\n  File \"/home/vagrant/addons/connector/producer.py\", line 43, in create\n    record_id = create_original(self, cr, uid, vals, context=context)\n  File \"/usr/lib/pymodules/python2.7/openerp/osv/orm.py\", line 4394, in create\n    if vals.pop(f, None) is not None:\nAttributeError: 'MapRecord' object has no attribute 'pop'\n```\n\nI thing that `vals` is equal to None \n", "reactions": {"url": "https://api.github.com/repos/waltervargas/prestashoperpconnect/issues/comments/50225766/reactions", "total_count": 0, "+1": 0, "-1": 0, "laugh": 0, "hooray": 0, "confused": 0, "heart": 0}, "author_association": "OWNER"}, {"url": "https://api.github.com/repos/waltervargas/prestashoperpconnect/issues/comments/52142681", "body": "Problem fixed in the commit cd261e25b9a122bab55415ebde0bbf5ed7780917\n", "reactions": {"url": "https://api.github.com/repos/waltervargas/prestashoperpconnect/issues/comments/52142681/reactions", "total_count": 0, "+1": 0, "-1": 0, "laugh": 0, "hooray": 0, "confused": 0, "heart": 0}, "author_association": "OWNER"}], "commit_comments": [], "review_comments": []}, "guerrerocarlos": {"issues": [], "commits": [], "pull_requests": [], "issue_comments": [{"url": "https://api.github.com/repos/waltervargas/prestashoperpconnect/issues/comments/49922570", "body": "En https://github.com/waltervargas/prestashoperpconnect/blob/master/prestashoperpconnect/unit/import_synchronizer.py#L102\n\nreemplacen:\n  return erp_id \n\npor:\n return [erp_id]\n\nAparentemente se espera que devuelva es una lista a la que se le pueda hacer \".pop()\"\nhttps://docs.python.org/2/tutorial/datastructures.html#more-on-lists\n", "reactions": {"url": "https://api.github.com/repos/waltervargas/prestashoperpconnect/issues/comments/49922570/reactions", "total_count": 0, "+1": 0, "-1": 0, "laugh": 0, "hooray": 0, "confused": 0, "heart": 0}, "author_association": "NONE"}], "commit_comments": [], "review_comments": []}, "anex": {"issues": [], "commits": [], "pull_requests": [], "issue_comments": [{"url": "https://api.github.com/repos/waltervargas/prestashoperpconnect/issues/comments/55366154", "body": "After try fix the above error:\n\n``` python\norders = record._source['associations'].get('order_rows', {}).get('order_row', [])\n```\n\nI get the following error:\n\n``` python\n2014-09-12 06:24:09,770 6523 ERROR salling openerp.addons.connector.queue.worker: Traceback (most recent call last):\n  File \"/opt/openerp/addons-connector/connector/queue/worker.py\", line 122, in run_job\n    job.perform(session)\n  File \"/opt/openerp/addons-connector/connector/queue/job.py\", line 490, in perform\n    self.result = self.func(session, *self.args, **self.kwargs)\n  File \"/opt/openerp/addons-connector/prestashoperpconnect/unit/import_synchronizer.py\", line 1036, in import_record\n    importer.run(prestashop_id)\n  File \"/opt/openerp/addons-connector/prestashoperpconnect/unit/import_synchronizer.py\", line 149, in run\n    erp_id = self._create(record)\n  File \"/opt/openerp/addons-connector/prestashoperpconnect/unit/import_synchronizer.py\", line 92, in _create\n    vals = data.values()\n  File \"/opt/openerp/addons-connector/connector/unit/mapper.py\", line 902, in values\n    values = self._mapper._apply(self, options=options)\n  File \"/opt/openerp/addons-connector/connector/unit/mapper.py\", line 641, in _apply\n    return self._apply_with_options(map_record)\n  File \"/opt/openerp/addons-connector/connector/unit/mapper.py\", line 691, in _apply_with_options\n    to_attr, model_name)\n  File \"/opt/openerp/addons-connector/prestashoperpconnect/unit/mapper.py\", line 414, in _map_child\n    mapper = self._init_child_mapper(model_name)\nAttributeError: 'SaleOrderMapper' object has no attribute '_init_child_mapper'\n```\n", "reactions": {"url": "https://api.github.com/repos/waltervargas/prestashoperpconnect/issues/comments/55366154/reactions", "total_count": 0, "+1": 0, "-1": 0, "laugh": 0, "hooray": 0, "confused": 0, "heart": 0}, "author_association": "COLLABORATOR"}], "commit_comments": [], "review_comments": []}, "percevaq": {"issues": [], "commits": [], "pull_requests": [], "issue_comments": [{"url": "https://api.github.com/repos/waltervargas/prestashoperpconnect/issues/comments/64949329", "body": "Hello:\nYou fix this problem?\n\nThank\n", "reactions": {"url": "https://api.github.com/repos/waltervargas/prestashoperpconnect/issues/comments/64949329/reactions", "total_count": 0, "+1": 0, "-1": 0, "laugh": 0, "hooray": 0, "confused": 0, "heart": 0}, "author_association": "NONE"}], "commit_comments": [], "review_comments": []}, "mytika": {"issues": [], "commits": [], "pull_requests": [], "issue_comments": [], "commit_comments": [{"url": "https://api.github.com/repos/waltervargas/prestashoperpconnect/comments/7414948", "body": "Hello Walter\nCould you tell me why here does not work? i'm error :\nthierry@toto:~/prestashopconnect_deps$ git clone git@github.com:OCA/connector.git\nCloning into 'connector'...\nPermission denied (publickey).\nfatal: The remote end hung up unexpectedly\nthierry@toto:~/prestashopconnect_deps$ \n\nCould you tell me what to do to make it work.\nThank you in advance\nbest regards\nThierry\n", "reactions": {"url": "https://api.github.com/repos/waltervargas/prestashoperpconnect/comments/7414948/reactions", "total_count": 0, "+1": 0, "-1": 0, "laugh": 0, "hooray": 0, "confused": 0, "heart": 0}, "author_association": "NONE"}], "review_comments": []}}}}